Workbook

Sheet Model Cover
A1: Luxewall
A2: Paint manufacturing Company
A4: By Fasih

Sheet Assumptions
A1: Start Year | B1: 2026
D2: 2026 | E2: 2027 | F2: 2028 | G2: 2029 | H2: 2030
A4: Macroeconomics
A5: Inflation Rate - Local | D5: 0.1 | E5: 0.09 | F5: 0.08 | G5: 0.07 | H5: 0.065
A6: Inflation Rate - Foreign | D6: 0.03 | E6: 0.028 | F6: 0.026 | G6: 0.025 | H6: 0.025
A7: USD/PKR Exchange Rate | D7: 285 | E7: 295 | F7: 305 | G7: 315 | H7: 325
A8: 6M KIBOR | D8: 0.13 | E8: 0.125 | F8: 0.12 | G8: 0.115 | H8: 0.11
A9: PKR depreciation | B9: 0.06
A10: Products & Sales
B11: Unit (Drummi) | C11: 1st Yr Sales Volume | D11: 1st Yr Sales Price (PKR) | E11: 1st Yr Sales Price (USD) | H11: Unit ( Gallon) | I11: =C11 -> 1st Yr Sales Volume | J11: =D11 -> 1st Yr Sales Price (PKR) | K11: =E11 -> 1st Yr Sales Price (USD) | N11: Unit (Quarter) | O11: =I11 -> 1st Yr Sales Volume | P11: =J11 -> 1st Yr Sales Price (PKR) | Q11: =K11 -> 1st Yr Sales Price (USD)
A12: Royal Matt Emulsion paint | B12: 16L (Drummi) | C12: 25000 | D12: 16953 | E12: =D12/$D$7 -> 59.484211 | G12: =A12 -> Royal Matt Emulsion paint | H12: 4L (Gallon) | I12: 30000 | J12: 4392 | K12: =J12/$D$7 -> 15.410526 | M12: =G12 -> Royal Matt Emulsion paint | N12: 1L (Quarter) | O12: 15000 | P12: 1141 | Q12: =P12/$D$7 -> 4.0035088
A13: Anti-bacterial Interior paint | B13: 16L (Drummi) | C13: 18000 | D13: 27840 | E13: =D13/$D$7 -> 97.684211 | G13: =A13 -> Anti-bacterial Interior paint | H13: 4L (Gallon) | I13: 23000 | J13: 6960 | K13: =J13/$D$7 -> 24.421053 | M13: =G13 -> Anti-bacterial Interior paint | N13: 1L (Quarter) | O13: 13000 | P13: 1740 | Q13: =P13/$D$7 -> 6.1052632
A14: Silk emulsion | B14: 16L (Drummi) | C14: 23000 | D14: 18445 | E14: =D14/$D$7 -> 64.719298 | G14: =A14 -> Silk emulsion | H14: 4L (Gallon) | I14: 27000 | J14: 4785 | K14: =J14/$D$7 -> 16.789474 | M14: =G14 -> Silk emulsion | N14: 1L (Quarter) | O14: 17000 | P14: 1196 | Q14: =P14/$D$7 -> 4.1964912
A15: Weather resistent exterior paint | B15: 16L (Drummi) | C15: 30000 | D15: 13168 | E15: =D15/$D$7 -> 46.203509 | G15: =A15 -> Weather resistent exterior paint | H15: 4L (Gallon) | I15: 35000 | J15: 3430 | K15: =J15/$D$7 -> 12.035088 | M15: =G15 -> Weather resistent exterior paint | N15: 1L (Quarter) | O15: 25000 | P15: 930 | Q15: =P15/$D$7 -> 3.2631579
A16: Super primer | B16: 16L (Drummi) | C16: 35000 | D16: 5165 | E16: =D16/$D$7 -> 18.122807 | G16: =A16 -> Super primer | H16: 4L (Gallon) | I16: 40000 | J16: 1369 | K16: =J16/$D$7 -> 4.8035088 | M16: =G16 -> Super primer | N16: 1L (Quarter) | O16: 30000 | P16: 342 | Q16: =P16/$D$7 -> 1.2
A17: Synthetic Enamel | B17: 16L(Drummi) | C17: 40000 | D17: 15968 | E17: =D17/$D$7 -> 56.02807 | G17: =A17 -> Synthetic Enamel | H17: 4L (Gallon) | I17: 45000 | J17: 3992 | K17: =J17/$D$7 -> 14.007018 | M17: =G17 -> Synthetic Enamel | N17: 1L (Quarter) | O17: 35000 | P17: 998 | Q17: =P17/$D$7 -> 3.5017544
A19: Sales Growth Rates
C20: =+D2 -> 2026 | D20: =+E2 -> 2027 | E20: =+F2 -> 2028 | F20: =+G2 -> 2029 | G20: =+H2 -> 2030
A21: Sales Volume Growth | C21: 0 | D21: 0.9 | E21: 0.8 | F21: 0.6 | G21: 0.4
A22: Sales Price Growth (Local) | C22: 0 | D22: 0.1 | E22: 0.09 | F22: 0.08 | G22: 0.07
A23: Sales Price Growth (Export) | C23: 0 | D23: 0.03 | E23: 0.03 | F23: 0.025 | G23: 0.035
A24: Export Share | C24: 0 | D24: 0.2 | E24: 0.25 | F24: 0.25 | G24: 0.3
A26: Taxes
A27: Sales Tax Rate | C27: 0.18
A28: Income Tax Rate | C28: 0.29
A30: Costs & Expenses Assumptions
A32: DIRECT COSTS (INPUTS)
A33: RAW MATERIAL BREAKDOWN Drummi | I33: RAW MATERIAL BREAKDOWN Gallon | Q33: RAW MATERIAL BREAKDOWN Litre
A34: 1. Royal Matt Emulsion paint | B34: units | C34: 2026 PKR per drummi | D34: 2027 | E34: 2028 | F34: 2029 | G34: 2030 | I34: 1. Royal Matt Emulsion paint | J34: units | K34: 2026 PKR per gallon | L34: 2027 | M34: 2028 | N34: 2029 | O34: 2030 | Q34: 1. Royal Matt Emulsion paint | R34: units | S34: 2026 PKR per Litre | T34: 2027 | U34: 2028 | V34: 2029 | W34: 2030
A35: Water | B35: 7.2 | C35: 288 | D35: =C35*(1+E$5) -> 313.92 | E35: =D35*(1+F$5) -> 339.0336 | F35: =E35*(1+G$5) -> 362.76595 | G35: =F35*(1+H$5) -> 386.34574 | I35: Water | J35: =$B35/4 -> 1.8 | K35: =C35/4 -> 72 | L35: =D35/4 -> 78.48 | M35: =E35/4 -> 84.7584 | N35: =F35/4 -> 90.691488 | O35: =G35/4 -> 96.586435 | Q35: Water | R35: =B35/16 -> 0.45 | S35: =C35/16 -> 18 | T35: =D35/16 -> 19.62 | U35: =E35/16 -> 21.1896 | V35: =F35/16 -> 22.672872 | W35: =G35/16 -> 24.146609
A36: Calcium Carbonate | B36: 4.8 | C36: 168 | D36: =C36*(1+E$5) -> 183.12 | E36: =D36*(1+F$5) -> 197.7696 | F36: =E36*(1+G$5) -> 211.61347 | G36: =F36*(1+H$5) -> 225.36835 | I36: Calcium Carbonate | J36: =$B36/4 -> 1.2 | K36: =C36/4 -> 42 | L36: =D36/4 -> 45.78 | M36: =E36/4 -> 49.4424 | N36: =F36/4 -> 52.903368 | O36: =G36/4 -> 56.342087 | Q36: Calcium Carbonate | R36: =B36/16 -> 0.3 | S36: =C36/16 -> 10.5 | T36: =D36/16 -> 11.445 | U36: =E36/16 -> 12.3606 | V36: =F36/16 -> 13.225842 | W36: =G36/16 -> 14.085522
A37: Titanium Dioxide (imported) | B37: 1.9 | C37: 2280 | D37: =C37*(1+E$6+$B$9) -> 2480.64 | E37: =D37*(1+F$6+$B$9) -> 2693.975 | F37: =E37*(1+G$6+$B$9) -> 2922.9629 | G37: =F37*(1+H$6+$B$9) -> 3171.4148 | I37: Titanium Dioxide (imported) | J37: =$B37/4 -> 0.475 | K37: =C37/4 -> 570 | L37: =D37/4 -> 620.16 | M37: =E37/4 -> 673.49376 | N37: =F37/4 -> 730.74073 | O37: =G37/4 -> 792.85369 | Q37: Titanium Dioxide (imported) | R37: =B37/16 -> 0.11875 | S37: =C37/16 -> 142.5 | T37: =D37/16 -> 155.04 | U37: =E37/16 -> 168.37344 | V37: =F37/16 -> 182.68518 | W37: =G37/16 -> 198.21342
A38: Acrylic Binder | B38: 1.4 | C38: 910 | D38: =C38*(1+E$5) -> 991.9 | E38: =D38*(1+F$5) -> 1071.252 | F38: =E38*(1+G$5) -> 1146.2396 | G38: =F38*(1+H$5) -> 1220.7452 | I38: Acrylic Binder | J38: =$B38/4 -> 0.35 | K38: =C38/4 -> 227.5 | L38: =D38/4 -> 247.975 | M38: =E38/4 -> 267.813 | N38: =F38/4 -> 286.55991 | O38: =G38/4 -> 305.1863 | Q38: Acrylic Binder | R38: =B38/16 -> 0.0875 | S38: =C38/16 -> 56.875 | T38: =D38/16 -> 61.99375 | U38: =E38/16 -> 66.95325 | V38: =F38/16 -> 71.639978 | W38: =G38/16 -> 76.296576
A39: Other Additives | B39: 0.15 | C39: 150 | D39: =C39*(1+E$5) -> 163.5 | E39: =D39*(1+F$5) -> 176.58 | F39: =E39*(1+G$5) -> 188.9406 | G39: =F39*(1+H$5) -> 201.22174 | I39: Other Additives | J39: =$B39/4 -> 0.0375 | K39: =C39/4 -> 37.5 | L39: =D39/4 -> 40.875 | M39: =E39/4 -> 44.145 | N39: =F39/4 -> 47.23515 | O39: =G39/4 -> 50.305435 | Q39: Other Additives | R39: =B39/16 -> 0.009375 | S39: =C39/16 -> 9.375 | T39: =D39/16 -> 10.21875 | U39: =E39/16 -> 11.03625 | V39: =F39/16 -> 11.808787 | W39: =G39/16 -> 12.576359
A40: Color pigments (Imported) | B40: 0.08 | C40: 80 | D40: =C40*(1+E$6+$B$9) -> 87.04 | E40: =D40*(1+F$6+$B$9) -> 94.52544 | F40: =E40*(1+G$6+$B$9) -> 102.5601 | G40: =F40*(1+H$6+$B$9) -> 111.27771 | I40: Color pigments (Imported) | J40: =$B40/4 -> 0.02 | K40: =C40/4 -> 20 | L40: =D40/4 -> 21.76 | M40: =E40/4 -> 23.63136 | N40: =F40/4 -> 25.640026 | O40: =G40/4 -> 27.819428 | Q40: Color pigments (Imported) | R40: =B40/16 -> 0.005 | S40: =C40/16 -> 5 | T40: =D40/16 -> 5.44 | U40: =E40/16 -> 5.90784 | V40: =F40/16 -> 6.4100064 | W40: =G40/16 -> 6.9548569
A41: Total Material Cost | C41: =SUM(C35:C40) -> 3876 | D41: =SUM(D35:D40) -> 4220.12 | E41: =SUM(E35:E40) -> 4573.1357 | F41: =SUM(F35:F40) -> 4935.0827 | G41: =SUM(G35:G40) -> 5316.3735 | I41: Total Material Cost | K41: =C41/4 -> 969 | L41: =D41/4 -> 1055.03 | M41: =E41/4 -> 1143.2839 | N41: =F41/4 -> 1233.7707 | O41: =G41/4 -> 1329.0934 | Q41: Total Material Cost | S41: =SUM(S35:S40) -> 242.25 | T41: =SUM(T35:T40) -> 263.7575 | U41: =SUM(U35:U40) -> 285.82098 | V41: =SUM(V35:V40) -> 308.44267 | W41: =SUM(W35:W40) -> 332.27335
A43: 2. Anti-bacterial Interior paint | B43: =B34 -> units | C43: =C34 -> 2026 PKR per drummi | D43: =D34 -> 2027 | E43: =E34 -> 2028 | F43: =F34 -> 2029 | G43: =G34 -> 2030 | I43: 2. Anti-bacterial Interior paint | J43: =J34 -> units | K43: =K34 -> 2026 PKR per gallon | L43: =L34 -> 2027 | M43: =M34 -> 2028 | N43: =N34 -> 2029 | O43: =O34 -> 2030 | Q43: 2. Anti-bacterial Interior paint | R43: =R34 -> units | S43: =S34 -> 2026 PKR per Litre | T43: =T34 -> 2027 | U43: =U34 -> 2028 | V43: =V34 -> 2029 | W43: =W34 -> 2030
A44: Water | B44: 6.7 | C44: 268 | D44: =C44*(1+E$5) -> 292.12 | E44: =D44*(1+F$5) -> 315.4896 | F44: =E44*(1+G$5) -> 337.57387 | G44: =F44*(1+H$5) -> 359.51617 | I44: Water | J44: =$B44/4 -> 1.675 | K44: =C44/4 -> 67 | L44: =D44/4 -> 73.03 | M44: =E44/4 -> 78.8724 | N44: =F44/4 -> 84.393468 | O44: =G44/4 -> 89.879043 | Q44: Water | R44: =B44/16 -> 0.41875 | S44: =C44/16 -> 16.75 | T44: =D44/16 -> 18.2575 | U44: =E44/16 -> 19.7181 | V44: =F44/16 -> 21.098367 | W44: =G44/16 -> 22.469761
A45: Calcium Carbonate | B45: 4.2 | C45: 147 | D45: =C45*(1+E$5) -> 160.23 | E45: =D45*(1+F$5) -> 173.0484 | F45: =E45*(1+G$5) -> 185.16179 | G45: =F45*(1+H$5) -> 197.1973 | I45: Calcium Carbonate | J45: =$B45/4 -> 1.05 | K45: =C45/4 -> 36.75 | L45: =D45/4 -> 40.0575 | M45: =E45/4 -> 43.2621 | N45: =F45/4 -> 46.290447 | O45: =G45/4 -> 49.299326 | Q45: Calcium Carbonate | R45: =B45/16 -> 0.2625 | S45: =C45/16 -> 9.1875 | T45: =D45/16 -> 10.014375 | U45: =E45/16 -> 10.815525 | V45: =F45/16 -> 11.572612 | W45: =G45/16 -> 12.324832
A46: Titanium Dioxide (imported) | B46: 2.2 | C46: 2640 | D46: =C46*(1+E$6+$B$9) -> 2872.32 | E46: =D46*(1+F$6+$B$9) -> 3119.3395 | F46: =E46*(1+G$6+$B$9) -> 3384.4834 | G46: =F46*(1+H$6+$B$9) -> 3672.1645 | I46: Titanium Dioxide (imported) | J46: =$B46/4 -> 0.55 | K46: =C46/4 -> 660 | L46: =D46/4 -> 718.08 | M46: =E46/4 -> 779.83488 | N46: =F46/4 -> 846.12084 | O46: =G46/4 -> 918.04112 | Q46: Titanium Dioxide (imported) | R46: =B46/16 -> 0.1375 | S46: =C46/16 -> 165 | T46: =D46/16 -> 179.52 | U46: =E46/16 -> 194.95872 | V46: =F46/16 -> 211.53021 | W46: =G46/16 -> 229.51028
...

Sheet Sales
A1: Sales
A2: Drummi | I2: Gallon | P2: Litre
A3: Sales Volume Drummi | B3: (NO) | I3: Sales Volume Gallon | J3: =B3 -> (NO) | P3: Sales Vol Litre
A4: Total sales | C4: =Assumptions!D2 -> 2026 | D4: =Assumptions!E2 -> 2027 | E4: =Assumptions!F2 -> 2028 | F4: =Assumptions!G2 -> 2029 | G4: =Assumptions!H2 -> 2030 | I4: =A4 -> Total sales | J4: =C4 -> 2026 | K4: =D4 -> 2027 | L4: =E4 -> 2028 | M4: =F4 -> 2029 | N4: =G4 -> 2030 | P4: =I4 -> Total sales | Q4: =J4 -> 2026 | R4: =K4 -> 2027 | S4: =L4 -> 2028 | T4: =M4 -> 2029 | U4: =N4 -> 2030
A5: =Assumptions!A12 -> Royal Matt Emulsion paint | C5: =Assumptions!C12 -> 25000 | D5: =C5*(1+Assumptions!D$21) -> 47500 | E5: =D5*(1+Assumptions!E$21) -> 85500 | F5: =E5*(1+Assumptions!F$21) -> 136800 | G5: =F5*(1+Assumptions!G$21) -> 191520 | I5: =A5 -> Royal Matt Emulsion paint | J5: =Assumptions!I12 -> 30000 | K5: =J5*(1+Assumptions!D$21) -> 57000 | L5: =K5*(1+Assumptions!E$21) -> 102600 | M5: =L5*(1+Assumptions!F$21) -> 164160 | N5: =M5*(1+Assumptions!G$21) -> 229824 | P5: =I5 -> Royal Matt Emulsion paint | Q5: =Assumptions!O12 -> 15000 | R5: =Q5*(1+Assumptions!D$21) -> 28500 | S5: =R5*(1+Assumptions!E$21) -> 51300 | T5: =S5*(1+Assumptions!F$21) -> 82080 | U5: =T5*(1+Assumptions!G$21) -> 114912
A6: =Assumptions!A13 -> Anti-bacterial Interior paint | C6: =Assumptions!C13 -> 18000 | D6: =C6*(1+Assumptions!D$21) -> 34200 | E6: =D6*(1+Assumptions!E$21) -> 61560 | F6: =E6*(1+Assumptions!F$21) -> 98496 | G6: =F6*(1+Assumptions!G$21) -> 137894.4 | I6: =A6 -> Anti-bacterial Interior paint | J6: =Assumptions!I13 -> 23000 | K6: =J6*(1+Assumptions!D$21) -> 43700 | L6: =K6*(1+Assumptions!E$21) -> 78660 | M6: =L6*(1+Assumptions!F$21) -> 125856 | N6: =M6*(1+Assumptions!G$21) -> 176198.4 | P6: =I6 -> Anti-bacterial Interior paint | Q6: =Assumptions!O13 -> 13000 | R6: =Q6*(1+Assumptions!D$21) -> 24700 | S6: =R6*(1+Assumptions!E$21) -> 44460 | T6: =S6*(1+Assumptions!F$21) -> 71136 | U6: =T6*(1+Assumptions!G$21) -> 99590.4
A7: =Assumptions!A14 -> Silk emulsion | C7: =Assumptions!C14 -> 23000 | D7: =C7*(1+Assumptions!D$21) -> 43700 | E7: =D7*(1+Assumptions!E$21) -> 78660 | F7: =E7*(1+Assumptions!F$21) -> 125856 | G7: =F7*(1+Assumptions!G$21) -> 176198.4 | I7: =A7 -> Silk emulsion | J7: =Assumptions!I14 -> 27000 | K7: =J7*(1+Assumptions!D$21) -> 51300 | L7: =K7*(1+Assumptions!E$21) -> 92340 | M7: =L7*(1+Assumptions!F$21) -> 147744 | N7: =M7*(1+Assumptions!G$21) -> 206841.6 | P7: =I7 -> Silk emulsion | Q7: =Assumptions!O14 -> 17000 | R7: =Q7*(1+Assumptions!D$21) -> 32300 | S7: =R7*(1+Assumptions!E$21) -> 58140 | T7: =S7*(1+Assumptions!F$21) -> 93024 | U7: =T7*(1+Assumptions!G$21) -> 130233.6
A8: =Assumptions!A15 -> Weather resistent exterior paint | C8: =Assumptions!C15 -> 30000 | D8: =C8*(1+Assumptions!D$21) -> 57000 | E8: =D8*(1+Assumptions!E$21) -> 102600 | F8: =E8*(1+Assumptions!F$21) -> 164160 | G8: =F8*(1+Assumptions!G$21) -> 229824 | I8: =A8 -> Weather resistent exterior paint | J8: =Assumptions!I15 -> 35000 | K8: =J8*(1+Assumptions!D$21) -> 66500 | L8: =K8*(1+Assumptions!E$21) -> 119700 | M8: =L8*(1+Assumptions!F$21) -> 191520 | N8: =M8*(1+Assumptions!G$21) -> 268128 | P8: =I8 -> Weather resistent exterior paint | Q8: =Assumptions!O15 -> 25000 | R8: =Q8*(1+Assumptions!D$21) -> 47500 | S8: =R8*(1+Assumptions!E$21) -> 85500 | T8: =S8*(1+Assumptions!F$21) -> 136800 | U8: =T8*(1+Assumptions!G$21) -> 191520
A9: =Assumptions!A16 -> Super primer | C9: =Assumptions!C16 -> 35000 | D9: =C9*(1+Assumptions!D$21) -> 66500 | E9: =D9*(1+Assumptions!E$21) -> 119700 | F9: =E9*(1+Assumptions!F$21) -> 191520 | G9: =F9*(1+Assumptions!G$21) -> 268128 | I9: =A9 -> Super primer | J9: =Assumptions!I16 -> 40000 | K9: =J9*(1+Assumptions!D$21) -> 76000 | L9: =K9*(1+Assumptions!E$21) -> 136800 | M9: =L9*(1+Assumptions!F$21) -> 218880 | N9: =M9*(1+Assumptions!G$21) -> 306432 | P9: =I9 -> Super primer | Q9: =Assumptions!O16 -> 30000 | R9: =Q9*(1+Assumptions!D$21) -> 57000 | S9: =R9*(1+Assumptions!E$21) -> 102600 | T9: =S9*(1+Assumptions!F$21) -> 164160 | U9: =T9*(1+Assumptions!G$21) -> 229824
A10: =Assumptions!A17 -> Synthetic Enamel | C10: =Assumptions!C17 -> 40000 | D10: =C10*(1+Assumptions!D$21) -> 76000 | E10: =D10*(1+Assumptions!E$21) -> 136800 | F10: =E10*(1+Assumptions!F$21) -> 218880 | G10: =F10*(1+Assumptions!G$21) -> 306432 | I10: =A10 -> Synthetic Enamel | J10: =Assumptions!I17 -> 45000 | K10: =J10*(1+Assumptions!D$21) -> 85500 | L10: =K10*(1+Assumptions!E$21) -> 153900 | M10: =L10*(1+Assumptions!F$21) -> 246240 | N10: =M10*(1+Assumptions!G$21) -> 344736 | P10: =I10 -> Synthetic Enamel | Q10: =Assumptions!O17 -> 35000 | R10: =Q10*(1+Assumptions!D$21) -> 66500 | S10: =R10*(1+Assumptions!E$21) -> 119700 | T10: =S10*(1+Assumptions!F$21) -> 191520 | U10: =T10*(1+Assumptions!G$21) -> 268128
P11: =I11
A12: Export Sales | C12: =C4 -> 2026 | D12: =D4 -> 2027 | E12: =E4 -> 2028 | F12: =F4 -> 2029 | G12: =G4 -> 2030 | I12: =A12 -> Export Sales | J12: =C12 -> 2026 | K12: =D12 -> 2027 | L12: =E12 -> 2028 | M12: =F12 -> 2029 | N12: =G12 -> 2030 | P12: =I12 -> Export Sales | Q12: =Q4 -> 2026 | R12: =R4 -> 2027 | S12: =S4 -> 2028 | T12: =T4 -> 2029 | U12: =U4 -> 2030
A13: =A5 -> Royal Matt Emulsion paint | C13: =C5*Assumptions!C$24 -> 0 | D13: =D5*Assumptions!D$24 -> 9500 | E13: =E5*Assumptions!E$24 -> 21375 | F13: =F5*Assumptions!F$24 -> 34200 | G13: =G5*Assumptions!G$24 -> 57456 | I13: =A13 -> Royal Matt Emulsion paint | J13: =0 -> 0 | K13: =K5*Assumptions!D$24 -> 11400 | L13: =L5*Assumptions!E$24 -> 25650 | M13: =M5*Assumptions!F$24 -> 41040 | N13: =N5*Assumptions!G$24 -> 68947.2 | P13: =I13 -> Royal Matt Emulsion paint | Q13: =0 -> 0 | R13: =R5*Assumptions!D$24 -> 5700 | S13: =S5*Assumptions!E$24 -> 12825 | T13: =T5*Assumptions!F$24 -> 20520 | U13: =U5*Assumptions!G$24 -> 34473.6
A14: =A6 -> Anti-bacterial Interior paint | C14: =C6*Assumptions!C$24 -> 0 | D14: =D6*Assumptions!D$24 -> 6840 | E14: =E6*Assumptions!E$24 -> 15390 | F14: =F6*Assumptions!F$24 -> 24624 | G14: =G6*Assumptions!G$24 -> 41368.32 | I14: =A14 -> Anti-bacterial Interior paint | J14: =0 -> 0 | K14: =K6*Assumptions!D$24 -> 8740 | L14: =L6*Assumptions!E$24 -> 19665 | M14: =M6*Assumptions!F$24 -> 31464 | N14: =N6*Assumptions!G$24 -> 52859.52 | P14: =I14 -> Anti-bacterial Interior paint | Q14: =0 -> 0 | R14: =R6*Assumptions!D$24 -> 4940 | S14: =S6*Assumptions!E$24 -> 11115 | T14: =T6*Assumptions!F$24 -> 17784 | U14: =U6*Assumptions!G$24 -> 29877.12
A15: =A7 -> Silk emulsion | C15: =C7*Assumptions!C$24 -> 0 | D15: =D7*Assumptions!D$24 -> 8740 | E15: =E7*Assumptions!E$24 -> 19665 | F15: =F7*Assumptions!F$24 -> 31464 | G15: =G7*Assumptions!G$24 -> 52859.52 | I15: =A15 -> Silk emulsion | J15: =0 -> 0 | K15: =K7*Assumptions!D$24 -> 10260 | L15: =L7*Assumptions!E$24 -> 23085 | M15: =M7*Assumptions!F$24 -> 36936 | N15: =N7*Assumptions!G$24 -> 62052.48 | P15: =I15 -> Silk emulsion | Q15: =0 -> 0 | R15: =R7*Assumptions!D$24 -> 6460 | S15: =S7*Assumptions!E$24 -> 14535 | T15: =T7*Assumptions!F$24 -> 23256 | U15: =U7*Assumptions!G$24 -> 39070.08
A16: =A8 -> Weather resistent exterior paint | C16: =C8*Assumptions!C$24 -> 0 | D16: =D8*Assumptions!D$24 -> 11400 | E16: =E8*Assumptions!E$24 -> 25650 | F16: =F8*Assumptions!F$24 -> 41040 | G16: =G8*Assumptions!G$24 -> 68947.2 | I16: =A16 -> Weather resistent exterior paint | J16: =0 -> 0 | K16: =K8*Assumptions!D$24 -> 13300 | L16: =L8*Assumptions!E$24 -> 29925 | M16: =M8*Assumptions!F$24 -> 47880 | N16: =N8*Assumptions!G$24 -> 80438.4 | P16: =I16 -> Weather resistent exterior paint | Q16: =0 -> 0 | R16: =R8*Assumptions!D$24 -> 9500 | S16: =S8*Assumptions!E$24 -> 21375 | T16: =T8*Assumptions!F$24 -> 34200 | U16: =U8*Assumptions!G$24 -> 57456
A17: =A9 -> Super primer | C17: =C9*Assumptions!C$24 -> 0 | D17: =D9*Assumptions!D$24 -> 13300 | E17: =E9*Assumptions!E$24 -> 29925 | F17: =F9*Assumptions!F$24 -> 47880 | G17: =G9*Assumptions!G$24 -> 80438.4 | I17: =A17 -> Super primer | J17: =0 -> 0 | K17: =K9*Assumptions!D$24 -> 15200 | L17: =L9*Assumptions!E$24 -> 34200 | M17: =M9*Assumptions!F$24 -> 54720 | N17: =N9*Assumptions!G$24 -> 91929.6 | P17: =I17 -> Super primer | Q17: =0 -> 0 | R17: =R9*Assumptions!D$24 -> 11400 | S17: =S9*Assumptions!E$24 -> 25650 | T17: =T9*Assumptions!F$24 -> 41040 | U17: =U9*Assumptions!G$24 -> 68947.2
A18: =A10 -> Synthetic Enamel | C18: =C10*Assumptions!C$24 -> 0 | D18: =D10*Assumptions!D$24 -> 15200 | E18: =E10*Assumptions!E$24 -> 34200 | F18: =F10*Assumptions!F$24 -> 54720 | G18: =G10*Assumptions!G$24 -> 91929.6 | I18: =A18 -> Synthetic Enamel | J18: =0 -> 0 | K18: =K10*Assumptions!D$24 -> 17100 | L18: =L10*Assumptions!E$24 -> 38475 | M18: =M10*Assumptions!F$24 -> 61560 | N18: =N10*Assumptions!G$24 -> 103420.8 | P18: =I18 -> Synthetic Enamel | Q18: =0 -> 0 | R18: =R10*Assumptions!D$24 -> 13300 | S18: =S10*Assumptions!E$24 -> 29925 | T18: =T10*Assumptions!F$24 -> 47880 | U18: =U10*Assumptions!G$24 -> 80438.4
A19: =A11 | P19: =I19
A20: Local sales | C20: =C12 -> 2026 | D20: =D12 -> 2027 | E20: =E12 -> 2028 | F20: =F12 -> 2029 | G20: =G12 -> 2030 | I20: =A20 -> Local sales | J20: =C20 -> 2026 | K20: =D20 -> 2027 | L20: =E20 -> 2028 | M20: =F20 -> 2029 | N20: =G20 -> 2030 | P20: =I20 -> Local sales | Q20: =Q12 -> 2026 | R20: =R12 -> 2027 | S20: =S12 -> 2028 | T20: =T12 -> 2029 | U20: =U12 -> 2030
A21: =A13 -> Royal Matt Emulsion paint | C21: =C5 -> 25000 | D21: =D5-D13 -> 38000 | E21: =E5-E13 -> 64125 | F21: =F5-F13 -> 102600 | G21: =G5-G13 -> 134064 | I21: =A21 -> Royal Matt Emulsion paint | J21: =J5 -> 30000 | K21: =K5-K13 -> 45600 | L21: =L5-L13 -> 76950 | M21: =M5-M13 -> 123120 | N21: =N5-N13 -> 160876.8 | P21: =I21 -> Royal Matt Emulsion paint | Q21: =Q5-Q13 -> 15000 | R21: =R5-R13 -> 22800 | S21: =S5-S13 -> 38475 | T21: =T5-T13 -> 61560 | U21: =U5-U13 -> 80438.4
A22: =A14 -> Anti-bacterial Interior paint | C22: =C6 -> 18000 | D22: =D6-D14 -> 27360 | E22: =E6-E14 -> 46170 | F22: =F6-F14 -> 73872 | G22: =G6-G14 -> 96526.08 | I22: =A22 -> Anti-bacterial Interior paint | J22: =J6 -> 23000 | K22: =K6-K14 -> 34960 | L22: =L6-L14 -> 58995 | M22: =M6-M14 -> 94392 | N22: =N6-N14 -> 123338.88 | P22: =I22 -> Anti-bacterial Interior paint | Q22: =Q6-Q14 -> 13000 | R22: =R6-R14 -> 19760 | S22: =S6-S14 -> 33345 | T22: =T6-T14 -> 53352 | U22: =U6-U14 -> 69713.28
A23: =A15 -> Silk emulsion | C23: =C7 -> 23000 | D23: =D7-D15 -> 34960 | E23: =E7-E15 -> 58995 | F23: =F7-F15 -> 94392 | G23: =G7-G15 -> 123338.88 | I23: =A23 -> Silk emulsion | J23: =J7 -> 27000 | K23: =K7-K15 -> 41040 | L23: =L7-L15 -> 69255 | M23: =M7-M15 -> 110808 | N23: =N7-N15 -> 144789.12 | P23: =I23 -> Silk emulsion | Q23: =Q7-Q15 -> 17000 | R23: =R7-R15 -> 25840 | S23: =S7-S15 -> 43605 | T23: =T7-T15 -> 69768 | U23: =U7-U15 -> 91163.52
A24: =A16 -> Weather resistent exterior paint | C24: =C8 -> 30000 | D24: =D8-D16 -> 45600 | E24: =E8-E16 -> 76950 | F24: =F8-F16 -> 123120 | G24: =G8-G16 -> 160876.8 | I24: =A24 -> Weather resistent exterior paint | J24: =J8 -> 35000 | K24: =K8-K16 -> 53200 | L24: =L8-L16 -> 89775 | M24: =M8-M16 -> 143640 | N24: =N8-N16 -> 187689.6 | P24: =I24 -> Weather resistent exterior paint | Q24: =Q8-Q16 -> 25000 | R24: =R8-R16 -> 38000 | S24: =S8-S16 -> 64125 | T24: =T8-T16 -> 102600 | U24: =U8-U16 -> 134064
A25: =A17 -> Super primer | C25: =C9 -> 35000 | D25: =D9-D17 -> 53200 | E25: =E9-E17 -> 89775 | F25: =F9-F17 -> 143640 | G25: =G9-G17 -> 187689.6 | I25: =A25 -> Super primer | J25: =J9 -> 40000 | K25: =K9-K17 -> 60800 | L25: =L9-L17 -> 102600 | M25: =M9-M17 -> 164160 | N25: =N9-N17 -> 214502.4 | P25: =I25 -> Super primer | Q25: =Q9-Q17 -> 30000 | R25: =R9-R17 -> 45600 | S25: =S9-S17 -> 76950 | T25: =T9-T17 -> 123120 | U25: =U9-U17 -> 160876.8
A26: =A18 -> Synthetic Enamel | C26: =C10 -> 40000 | D26: =D10-D18 -> 60800 | E26: =E10-E18 -> 102600 | F26: =F10-F18 -> 164160 | G26: =G10-G18 -> 214502.4 | I26: =A26 -> Synthetic Enamel | J26: =J10 -> 45000 | K26: =K10-K18 -> 68400 | L26: =L10-L18 -> 115425 | M26: =M10-M18 -> 184680 | N26: =N10-N18 -> 241315.2 | P26: =I26 -> Synthetic Enamel | Q26: =Q10-Q18 -> 35000 | R26: =R10-R18 -> 53200 | S26: =S10-S18 -> 89775 | T26: =T10-T18 -> 143640 | U26: =U10-U18 -> 187689.6
P27: =I27
A28: Sales Price | I28: =A28 -> Sales Price | P28: =I28 -> Sales Price
P29: =I29
A30: Export Sales | C30: =C20 -> 2026 | D30: =D20 -> 2027 | E30: =E20 -> 2028 | F30: =F20 -> 2029 | G30: =G20 -> 2030 | I30: =A30 -> Export Sales | J30: =C30 -> 2026 | K30: =D30 -> 2027 | L30: =E30 -> 2028 | M30: =F30 -> 2029 | N30: =G30 -> 2030 | P30: =I30 -> Export Sales | Q30: =Q20 -> 2026 | R30: =R20 -> 2027 | S30: =S20 -> 2028 | T30: =T20 -> 2029 | U30: =U20 -> 2030
A31: =A21 -> Royal Matt Emulsion paint | C31: =Assumptions!E12 -> 59.484211 | D31: =C31*(1+Assumptions!D$23) -> 61.268737 | E31: =D31*(1+Assumptions!E$23) -> 63.106799 | F31: =E31*(1+Assumptions!F$23) -> 64.684469 | G31: =F31*(1+Assumptions!G$23) -> 66.948425 | I31: =A31 -> Royal Matt Emulsion paint | J31: =Assumptions!K12 -> 15.410526 | K31: =J31*(1+Assumptions!D$23) -> 15.872842 | L31: =K31*(1+Assumptions!E$23) -> 16.349027 | M31: =L31*(1+Assumptions!F$23) -> 16.757753 | N31: =M31*(1+Assumptions!G$23) -> 17.344274 | P31: =I31 -> Royal Matt Emulsion paint | Q31: =Assumptions!Q12 -> 4.0035088 | R31: =Q31*(1+Assumptions!D$23) -> 4.123614 | S31: =R31*(1+Assumptions!E$23) -> 4.2473225 | T31: =S31*(1+Assumptions!F$23) -> 4.3535055 | U31: =T31*(1+Assumptions!G$23) -> 4.5058782
A32: =A22 -> Anti-bacterial Interior paint | C32: =Assumptions!E13 -> 97.684211 | D32: =C32*(1+Assumptions!D$23) -> 100.61474 | E32: =D32*(1+Assumptions!E$23) -> 103.63318 | F32: =E32*(1+Assumptions!F$23) -> 106.22401 | G32: =F32*(1+Assumptions!G$23) -> 109.94185 | I32: =A32 -> Anti-bacterial Interior paint | J32: =Assumptions!K13 -> 24.421053 | K32: =J32*(1+Assumptions!D$23) -> 25.153684 | L32: =K32*(1+Assumptions!E$23) -> 25.908295 | M32: =L32*(1+Assumptions!F$23) -> 26.556002 | N32: =M32*(1+Assumptions!G$23) -> 27.485462 | P32: =I32 -> Anti-bacterial Interior paint | Q32: =Assumptions!Q13 -> 6.1052632 | R32: =Q32*(1+Assumptions!D$23) -> 6.2884211 | S32: =R32*(1+Assumptions!E$23) -> 6.4770737 | T32: =S32*(1+Assumptions!F$23) -> 6.6390005 | U32: =T32*(1+Assumptions!G$23) -> 6.8713655
A33: =A23 -> Silk emulsion | C33: =Assumptions!E14 -> 64.719298 | D33: =C33*(1+Assumptions!D$23) -> 66.660877 | E33: =D33*(1+Assumptions!E$23) -> 68.660704 | F33: =E33*(1+Assumptions!F$23) -> 70.377221 | G33: =F33*(1+Assumptions!G$23) -> 72.840424 | I33: =A33 -> Silk emulsion | J33: =Assumptions!K14 -> 16.789474 | K33: =J33*(1+Assumptions!D$23) -> 17.293158 | L33: =K33*(1+Assumptions!E$23) -> 17.811953 | M33: =L33*(1+Assumptions!F$23) -> 18.257251 | N33: =M33*(1+Assumptions!G$23) -> 18.896255 | P33: =I33 -> Silk emulsion | Q33: =Assumptions!Q14 -> 4.1964912 | R33: =Q33*(1+Assumptions!D$23) -> 4.322386 | S33: =R33*(1+Assumptions!E$23) -> 4.4520575 | T33: =S33*(1+Assumptions!F$23) -> 4.563359 | U33: =T33*(1+Assumptions!G$23) -> 4.7230765
A34: =A24 -> Weather resistent exterior paint | C34: =Assumptions!E15 -> 46.203509 | D34: =C34*(1+Assumptions!D$23) -> 47.589614 | E34: =D34*(1+Assumptions!E$23) -> 49.017302 | F34: =E34*(1+Assumptions!F$23) -> 50.242735 | G34: =F34*(1+Assumptions!G$23) -> 52.001231 | I34: =A34 -> Weather resistent exterior paint | J34: =Assumptions!K15 -> 12.035088 | K34: =J34*(1+Assumptions!D$23) -> 12.39614 | L34: =K34*(1+Assumptions!E$23) -> 12.768025 | M34: =L34*(1+Assumptions!F$23) -> 13.087225 | N34: =M34*(1+Assumptions!G$23) -> 13.545278 | P34: =I34 -> Weather resistent exterior paint | Q34: =Assumptions!Q15 -> 3.2631579 | R34: =Q34*(1+Assumptions!D$23) -> 3.3610526 | S34: =R34*(1+Assumptions!E$23) -> 3.4618842 | T34: =S34*(1+Assumptions!F$23) -> 3.5484313 | U34: =T34*(1+Assumptions!G$23) -> 3.6726264
A35: =A25 -> Super primer | C35: =Assumptions!E16 -> 18.122807 | D35: =C35*(1+Assumptions!D$23) -> 18.666491 | E35: =D35*(1+Assumptions!E$23) -> 19.226486 | F35: =E35*(1+Assumptions!F$23) -> 19.707148 | G35: =F35*(1+Assumptions!G$23) -> 20.396898 | I35: =A35 -> Super primer | J35: =Assumptions!K16 -> 4.8035088 | K35: =J35*(1+Assumptions!D$23) -> 4.947614 | L35: =K35*(1+Assumptions!E$23) -> 5.0960425 | M35: =L35*(1+Assumptions!F$23) -> 5.2234435 | N35: =M35*(1+Assumptions!G$23) -> 5.406264 | P35: =I35 -> Super primer | Q35: =Assumptions!Q16 -> 1.2 | R35: =Q35*(1+Assumptions!D$23) -> 1.236 | S35: =R35*(1+Assumptions!E$23) -> 1.27308 | T35: =S35*(1+Assumptions!F$23) -> 1.304907 | U35: =T35*(1+Assumptions!G$23) -> 1.3505787
A36: =A26 -> Synthetic Enamel | C36: =Assumptions!E17 -> 56.02807 | D36: =C36*(1+Assumptions!D$23) -> 57.708912 | E36: =D36*(1+Assumptions!E$23) -> 59.44018 | F36: =E36*(1+Assumptions!F$23) -> 60.926184 | G36: =F36*(1+Assumptions!G$23) -> 63.058601 | I36: =A36 -> Synthetic Enamel | J36: =Assumptions!K17 -> 14.007018 | K36: =J36*(1+Assumptions!D$23) -> 14.427228 | L36: =K36*(1+Assumptions!E$23) -> 14.860045 | M36: =L36*(1+Assumptions!F$23) -> 15.231546 | N36: =M36*(1+Assumptions!G$23) -> 15.76465 | P36: =I36 -> Synthetic Enamel | Q36: =Assumptions!Q17 -> 3.5017544 | R36: =Q36*(1+Assumptions!D$23) -> 3.606807 | S36: =R36*(1+Assumptions!E$23) -> 3.7150112 | T36: =S36*(1+Assumptions!F$23) -> 3.8078865 | U36: =T36*(1+Assumptions!G$23) -> 3.9411625
P37: =I37
A38: Local Sales | C38: =C30 -> 2026 | D38: =D30 -> 2027 | E38: =E30 -> 2028 | F38: =F30 -> 2029 | G38: =G30 -> 2030 | I38: =A38 -> Local Sales | J38: =C38 -> 2026 | K38: =D38 -> 2027 | L38: =E38 -> 2028 | M38: =F38 -> 2029 | N38: =G38 -> 2030 | P38: =I38 -> Local Sales | Q38: =Q30 -> 2026 | R38: =R30 -> 2027 | S38: =S30 -> 2028 | T38: =T30 -> 2029 | U38: =U30 -> 2030
A39: =A31 -> Royal Matt Emulsion paint | C39: =Assumptions!D12 -> 16953 | D39: =C39*(1+Assumptions!D$22) -> 18648.3 | E39: =D39*(1+Assumptions!E$22) -> 20326.647 | F39: =E39*(1+Assumptions!F$22) -> 21952.779 | G39: =F39*(1+Assumptions!G$22) -> 23489.473 | I39: =A39 -> Royal Matt Emulsion paint | J39: =Assumptions!J12 -> 4392 | K39: =J39*( 1+Assumptions!D$22) -> 4831.2 | L39: =K39*(1+Assumptions!E$22) -> 5266.008 | M39: =L39*(1+Assumptions!F$22) -> 5687.2886 | N39: =M39*(1+Assumptions!G$22) -> 6085.3988 | P39: =I39 -> Royal Matt Emulsion paint | Q39: =Assumptions!P12 -> 1141 | R39: =Q39*(1+Assumptions!D$22) -> 1255.1 | S39: =R39*(1+Assumptions!E$22) -> 1368.059 | T39: =S39*(1+Assumptions!F$22) -> 1477.5037 | U39: =T39*(1+Assumptions!G$22) -> 1580.929
A40: =A32 -> Anti-bacterial Interior paint | C40: =Assumptions!D13 -> 27840 | D40: =C40*(1+Assumptions!D$22) -> 30624 | E40: =D40*(1+Assumptions!E$22) -> 33380.16 | F40: =E40*(1+Assumptions!F$22) -> 36050.573 | G40: =F40*(1+Assumptions!G$22) -> 38574.113 | I40: =A40 -> Anti-bacterial Interior paint | J40: =Assumptions!J13 -> 6960 | K40: =J40*(1+Assumptions!D$22) -> 7656 | L40: =K40*(1+Assumptions!E$22) -> 8345.04 | M40: =L40*(1+Assumptions!F$22) -> 9012.6432 | N40: =M40*(1+Assumptions!G$22) -> 9643.5282 | P40: =I40 -> Anti-bacterial Interior paint | Q40: =Assumptions!P13 -> 1740 | R40: =Q40*(1+Assumptions!D$22) -> 1914 | S40: =R40*(1+Assumptions!E$22) -> 2086.26 | T40: =S40*(1+Assumptions!F$22) -> 2253.1608 | U40: =T40*(1+Assumptions!G$22) -> 2410.8821
...

Sheet Cost
A1: Cost
A2: DRUMMI | H2: GALLON | O2: LITRE
A3: Direct Labor | H3: =A3 -> Direct Labor | O3: =H3 -> Direct Labor
O4: =H4
A5: DL cost per product (PKR) | B5: =Sales!C4 -> 2026 | C5: =Sales!D4 -> 2027 | D5: =Sales!E4 -> 2028 | E5: =Sales!F4 -> 2029 | F5: =Sales!G4 -> 2030 | H5: =A5 -> DL cost per product (PKR) | I5: =B5 -> 2026 | J5: =C5 -> 2027 | K5: =D5 -> 2028 | L5: =E5 -> 2029 | M5: =F5 -> 2030 | O5: =H5 -> DL cost per product (PKR) | P5: =I5 -> 2026 | Q5: =J5 -> 2027 | R5: =K5 -> 2028 | S5: =L5 -> 2029 | T5: =M5 -> 2030
A6: =Sales!A5 -> Royal Matt Emulsion paint | B6: =Assumptions!$B91*Assumptions!B$99 -> 125 | C6: =Assumptions!$B91*Assumptions!C$99 -> 136.25 | D6: =Assumptions!$B91*Assumptions!D$99 -> 147.15 | E6: =Assumptions!$B91*Assumptions!E$99 -> 157.4505 | F6: =Assumptions!$B91*Assumptions!F$99 -> 167.68478 | H6: =A6 -> Royal Matt Emulsion paint | I6: =Assumptions!$C91*Assumptions!B$99 -> 31.25 | J6: =Assumptions!$C91*Assumptions!C$99 -> 34.0625 | K6: =Assumptions!$C91*Assumptions!D$99 -> 36.7875 | L6: =Assumptions!$C91*Assumptions!E$99 -> 39.362625 | M6: =Assumptions!$C91*Assumptions!F$99 -> 41.921196 | O6: =H6 -> Royal Matt Emulsion paint | P6: =Assumptions!$D91*Assumptions!B$99 -> 7.8125 | Q6: =Assumptions!$D91*Assumptions!C$99 -> 8.515625 | R6: =Assumptions!$D91*Assumptions!D$99 -> 9.196875 | S6: =Assumptions!$D91*Assumptions!E$99 -> 9.8406563 | T6: =Assumptions!$D91*Assumptions!F$99 -> 10.480299
A7: =Sales!A6 -> Anti-bacterial Interior paint | B7: =Assumptions!$B92*Assumptions!B$99 -> 225 | C7: =Assumptions!$B92*Assumptions!C$99 -> 245.25 | D7: =Assumptions!$B92*Assumptions!D$99 -> 264.87 | E7: =Assumptions!$B92*Assumptions!E$99 -> 283.4109 | F7: =Assumptions!$B92*Assumptions!F$99 -> 301.83261 | H7: =A7 -> Anti-bacterial Interior paint | I7: =Assumptions!$C92*Assumptions!B$99 -> 56.25 | J7: =Assumptions!$C92*Assumptions!C$99 -> 61.3125 | K7: =Assumptions!$C92*Assumptions!D$99 -> 66.2175 | L7: =Assumptions!$C92*Assumptions!E$99 -> 70.852725 | M7: =Assumptions!$C92*Assumptions!F$99 -> 75.458152 | O7: =H7 -> Anti-bacterial Interior paint | P7: =Assumptions!$D92*Assumptions!B$99 -> 14.0625 | Q7: =Assumptions!$D92*Assumptions!C$99 -> 15.328125 | R7: =Assumptions!$D92*Assumptions!D$99 -> 16.554375 | S7: =Assumptions!$D92*Assumptions!E$99 -> 17.713181 | T7: =Assumptions!$D92*Assumptions!F$99 -> 18.864538
A8: =Sales!A7 -> Silk emulsion | B8: =Assumptions!$B93*Assumptions!B$99 -> 150 | C8: =Assumptions!$B93*Assumptions!C$99 -> 163.5 | D8: =Assumptions!$B93*Assumptions!D$99 -> 176.58 | E8: =Assumptions!$B93*Assumptions!E$99 -> 188.9406 | F8: =Assumptions!$B93*Assumptions!F$99 -> 201.22174 | H8: =A8 -> Silk emulsion | I8: =Assumptions!$C93*Assumptions!B$99 -> 37.5 | J8: =Assumptions!$C93*Assumptions!C$99 -> 40.875 | K8: =Assumptions!$C93*Assumptions!D$99 -> 44.145 | L8: =Assumptions!$C93*Assumptions!E$99 -> 47.23515 | M8: =Assumptions!$C93*Assumptions!F$99 -> 50.305435 | O8: =H8 -> Silk emulsion | P8: =Assumptions!$D93*Assumptions!B$99 -> 9.375 | Q8: =Assumptions!$D93*Assumptions!C$99 -> 10.21875 | R8: =Assumptions!$D93*Assumptions!D$99 -> 11.03625 | S8: =Assumptions!$D93*Assumptions!E$99 -> 11.808787 | T8: =Assumptions!$D93*Assumptions!F$99 -> 12.576359
A9: =Sales!A8 -> Weather resistent exterior paint | B9: =Assumptions!$B94*Assumptions!B$99 -> 175 | C9: =Assumptions!$B94*Assumptions!C$99 -> 190.75 | D9: =Assumptions!$B94*Assumptions!D$99 -> 206.01 | E9: =Assumptions!$B94*Assumptions!E$99 -> 220.4307 | F9: =Assumptions!$B94*Assumptions!F$99 -> 234.7587 | H9: =A9 -> Weather resistent exterior paint | I9: =Assumptions!$C94*Assumptions!B$99 -> 43.75 | J9: =Assumptions!$C94*Assumptions!C$99 -> 47.6875 | K9: =Assumptions!$C94*Assumptions!D$99 -> 51.5025 | L9: =Assumptions!$C94*Assumptions!E$99 -> 55.107675 | M9: =Assumptions!$C94*Assumptions!F$99 -> 58.689674 | O9: =H9 -> Weather resistent exterior paint | P9: =Assumptions!$D94*Assumptions!B$99 -> 10.9375 | Q9: =Assumptions!$D94*Assumptions!C$99 -> 11.921875 | R9: =Assumptions!$D94*Assumptions!D$99 -> 12.875625 | S9: =Assumptions!$D94*Assumptions!E$99 -> 13.776919 | T9: =Assumptions!$D94*Assumptions!F$99 -> 14.672418
A10: =Sales!A9 -> Super primer | B10: =Assumptions!$B95*Assumptions!B$99 -> 100 | C10: =Assumptions!$B95*Assumptions!C$99 -> 109 | D10: =Assumptions!$B95*Assumptions!D$99 -> 117.72 | E10: =Assumptions!$B95*Assumptions!E$99 -> 125.9604 | F10: =Assumptions!$B95*Assumptions!F$99 -> 134.14783 | H10: =A10 -> Super primer | I10: =Assumptions!$C95*Assumptions!B$99 -> 25 | J10: =Assumptions!$C95*Assumptions!C$99 -> 27.25 | K10: =Assumptions!$C95*Assumptions!D$99 -> 29.43 | L10: =Assumptions!$C95*Assumptions!E$99 -> 31.4901 | M10: =Assumptions!$C95*Assumptions!F$99 -> 33.536957 | O10: =H10 -> Super primer | P10: =Assumptions!$D95*Assumptions!B$99 -> 6.25 | Q10: =Assumptions!$D95*Assumptions!C$99 -> 6.8125 | R10: =Assumptions!$D95*Assumptions!D$99 -> 7.3575 | S10: =Assumptions!$D95*Assumptions!E$99 -> 7.872525 | T10: =Assumptions!$D95*Assumptions!F$99 -> 8.3842391
A11: =Sales!A10 -> Synthetic Enamel | B11: =Assumptions!$B96*Assumptions!B$99 -> 200 | C11: =Assumptions!$B96*Assumptions!C$99 -> 218 | D11: =Assumptions!$B96*Assumptions!D$99 -> 235.44 | E11: =Assumptions!$B96*Assumptions!E$99 -> 251.9208 | F11: =Assumptions!$B96*Assumptions!F$99 -> 268.29565 | H11: =A11 -> Synthetic Enamel | I11: =Assumptions!$C96*Assumptions!B$99 -> 50 | J11: =Assumptions!$C96*Assumptions!C$99 -> 54.5 | K11: =Assumptions!$C96*Assumptions!D$99 -> 58.86 | L11: =Assumptions!$C96*Assumptions!E$99 -> 62.9802 | M11: =Assumptions!$C96*Assumptions!F$99 -> 67.073913 | O11: =H11 -> Synthetic Enamel | P11: =Assumptions!$D96*Assumptions!B$99 -> 12.5 | Q11: =Assumptions!$D96*Assumptions!C$99 -> 13.625 | R11: =Assumptions!$D96*Assumptions!D$99 -> 14.715 | S11: =Assumptions!$D96*Assumptions!E$99 -> 15.74505 | T11: =Assumptions!$D96*Assumptions!F$99 -> 16.768478
O12: =H12
A13: DL cost PKR Mn | B13: =B5 -> 2026 | C13: =C5 -> 2027 | D13: =D5 -> 2028 | E13: =E5 -> 2029 | F13: =F5 -> 2030 | H13: =A13 -> DL cost PKR Mn | I13: =B13 -> 2026 | J13: =C13 -> 2027 | K13: =D13 -> 2028 | L13: =E13 -> 2029 | M13: =F13 -> 2030 | O13: =H13 -> DL cost PKR Mn | P13: =I13 -> 2026 | Q13: =J13 -> 2027 | R13: =K13 -> 2028 | S13: =L13 -> 2029 | T13: =M13 -> 2030
A14: =A6 -> Royal Matt Emulsion paint | B14: =B6*Sales!C5/1000000 -> 3.125 | C14: =C6*Sales!D5/1000000 -> 6.471875 | D14: =D6*Sales!E5/1000000 -> 12.581325 | E14: =E6*Sales!F5/1000000 -> 21.539228 | F14: =F6*Sales!G5/1000000 -> 32.11499 | H14: =A14 -> Royal Matt Emulsion paint | I14: =I6*Sales!J5/1000000 -> 0.9375 | J14: =J6*Sales!K5/1000000 -> 1.9415625 | K14: =K6*Sales!L5/1000000 -> 3.7743975 | L14: =L6*Sales!M5/1000000 -> 6.4617685 | M14: =M6*Sales!N5/1000000 -> 9.6344969 | O14: =H14 -> Royal Matt Emulsion paint | P14: =P6*Sales!Q5/1000000 -> 0.1171875 | Q14: =Q6*Sales!R5/1000000 -> 0.24269531 | R14: =R6*Sales!S5/1000000 -> 0.47179969 | S14: =S6*Sales!T5/1000000 -> 0.80772106 | T14: =T6*Sales!U5/1000000 -> 1.2043121
A15: =A7 -> Anti-bacterial Interior paint | B15: =B7*Sales!C6/1000000 -> 4.05 | C15: =C7*Sales!D6/1000000 -> 8.38755 | D15: =D7*Sales!E6/1000000 -> 16.305397 | E15: =E7*Sales!F6/1000000 -> 27.91484 | F15: =F7*Sales!G6/1000000 -> 41.621026 | H15: =A15 -> Anti-bacterial Interior paint | I15: =I7*Sales!J6/1000000 -> 1.29375 | J15: =J7*Sales!K6/1000000 -> 2.6793563 | K15: =K7*Sales!L6/1000000 -> 5.2086685 | L15: =L7*Sales!M6/1000000 -> 8.9172406 | M15: =M7*Sales!N6/1000000 -> 13.295606 | O15: =H15 -> Anti-bacterial Interior paint | P15: =P7*Sales!Q6/1000000 -> 0.1828125 | Q15: =Q7*Sales!R6/1000000 -> 0.37860469 | R15: =R7*Sales!S6/1000000 -> 0.73600751 | S15: =S7*Sales!T6/1000000 -> 1.2600449 | T15: =T7*Sales!U6/1000000 -> 1.8787269
A16: =A8 -> Silk emulsion | B16: =B8*Sales!C7/1000000 -> 3.45 | C16: =C8*Sales!D7/1000000 -> 7.14495 | D16: =D8*Sales!E7/1000000 -> 13.889783 | E16: =E8*Sales!F7/1000000 -> 23.779308 | F16: =F8*Sales!G7/1000000 -> 35.454948 | H16: =A16 -> Silk emulsion | I16: =I8*Sales!J7/1000000 -> 1.0125 | J16: =J8*Sales!K7/1000000 -> 2.0968875 | K16: =K8*Sales!L7/1000000 -> 4.0763493 | L16: =L8*Sales!M7/1000000 -> 6.97871 | M16: =M8*Sales!N7/1000000 -> 10.405257 | O16: =H16 -> Silk emulsion | P16: =P8*Sales!Q7/1000000 -> 0.159375 | Q16: =Q8*Sales!R7/1000000 -> 0.33006562 | R16: =R8*Sales!S7/1000000 -> 0.64164758 | S16: =S8*Sales!T7/1000000 -> 1.0985006 | T16: =T8*Sales!U7/1000000 -> 1.6378645
A17: =A9 -> Weather resistent exterior paint | B17: =B9*Sales!C8/1000000 -> 5.25 | C17: =C9*Sales!D8/1000000 -> 10.87275 | D17: =D9*Sales!E8/1000000 -> 21.136626 | E17: =E9*Sales!F8/1000000 -> 36.185904 | F17: =F9*Sales!G8/1000000 -> 53.953182 | H17: =A17 -> Weather resistent exterior paint | I17: =I9*Sales!J8/1000000 -> 1.53125 | J17: =J9*Sales!K8/1000000 -> 3.1712187 | K17: =K9*Sales!L8/1000000 -> 6.1648492 | L17: =L9*Sales!M8/1000000 -> 10.554222 | M17: =M9*Sales!N8/1000000 -> 15.736345 | O17: =H17 -> Weather resistent exterior paint | P17: =P9*Sales!Q8/1000000 -> 0.2734375 | Q17: =Q9*Sales!R8/1000000 -> 0.56628906 | R17: =R9*Sales!S8/1000000 -> 1.1008659 | S17: =S9*Sales!T8/1000000 -> 1.8846825 | T17: =T9*Sales!U8/1000000 -> 2.8100616
A18: =A10 -> Super primer | B18: =B10*Sales!C9/1000000 -> 3.5 | C18: =C10*Sales!D9/1000000 -> 7.2485 | D18: =D10*Sales!E9/1000000 -> 14.091084 | E18: =E10*Sales!F9/1000000 -> 24.123936 | F18: =F10*Sales!G9/1000000 -> 35.968788 | H18: =A18 -> Super primer | I18: =I10*Sales!J9/1000000 -> 1 | J18: =J10*Sales!K9/1000000 -> 2.071 | K18: =K10*Sales!L9/1000000 -> 4.026024 | L18: =L10*Sales!M9/1000000 -> 6.8925531 | M18: =M10*Sales!N9/1000000 -> 10.276797 | O18: =H18 -> Super primer | P18: =P10*Sales!Q9/1000000 -> 0.1875 | Q18: =Q10*Sales!R9/1000000 -> 0.3883125 | R18: =R10*Sales!S9/1000000 -> 0.7548795 | S18: =S10*Sales!T9/1000000 -> 1.2923537 | T18: =T10*Sales!U9/1000000 -> 1.9268994
A19: =A11 -> Synthetic Enamel | B19: =B11*Sales!C10/1000000 -> 8 | C19: =C11*Sales!D10/1000000 -> 16.568 | D19: =D11*Sales!E10/1000000 -> 32.208192 | E19: =E11*Sales!F10/1000000 -> 55.140425 | F19: =F11*Sales!G10/1000000 -> 82.214373 | H19: =A19 -> Synthetic Enamel | I19: =I11*Sales!J10/1000000 -> 2.25 | J19: =J11*Sales!K10/1000000 -> 4.65975 | K19: =K11*Sales!L10/1000000 -> 9.058554 | L19: =L11*Sales!M10/1000000 -> 15.508244 | M19: =M11*Sales!N10/1000000 -> 23.122792 | O19: =H19 -> Synthetic Enamel | P19: =P11*Sales!Q10/1000000 -> 0.4375 | Q19: =Q11*Sales!R10/1000000 -> 0.9060625 | R19: =R11*Sales!S10/1000000 -> 1.7613855 | S19: =S11*Sales!T10/1000000 -> 3.015492 | T19: =T11*Sales!U10/1000000 -> 4.4960985
A20: Total DL cost | B20: =SUM(B14:B19) -> 27.375 | C20: =SUM(C14:C19) -> 56.693625 | D20: =SUM(D14:D19) -> 110.21241 | E20: =SUM(E14:E19) -> 188.68364 | F20: =SUM(F14:F19) -> 281.32731 | H20: =A20 -> Total DL cost | I20: =SUM(I14:I19) -> 8.025 | J20: =SUM(J14:J19) -> 16.619775 | K20: =SUM(K14:K19) -> 32.308843 | L20: =SUM(L14:L19) -> 55.312739 | M20: =SUM(M14:M19) -> 82.471293 | O20: =H20 -> Total DL cost | P20: =SUM(P14:P19) -> 1.3578125 | Q20: =SUM(Q14:Q19) -> 2.8120297 | R20: =SUM(R14:R19) -> 5.4665857 | S20: =SUM(S14:S19) -> 9.3587947 | T20: =SUM(T14:T19) -> 13.953963
O21: =H21
A22: Raw Material Cost | H22: =A22 -> Raw Material Cost | O22: =H22 -> Raw Material Cost
O23: =H23
A24: Raw material Cost per product | B24: =B13 -> 2026 | C24: =C13 -> 2027 | D24: =D13 -> 2028 | E24: =E13 -> 2029 | F24: =F13 -> 2030 | H24: =A24 -> Raw material Cost per product | I24: =B24 -> 2026 | J24: =C24 -> 2027 | K24: =D24 -> 2028 | L24: =E24 -> 2029 | M24: =F24 -> 2030 | O24: =H24 -> Raw material Cost per product | P24: =I24 -> 2026 | Q24: =J24 -> 2027 | R24: =K24 -> 2028 | S24: =L24 -> 2029 | T24: =M24 -> 2030
A25: =A14 -> Royal Matt Emulsion paint | B25: =Assumptions!C41 -> 3876 | C25: =Assumptions!D41 -> 4220.12 | D25: =Assumptions!E41 -> 4573.1357 | E25: =Assumptions!F41 -> 4935.0827 | F25: =Assumptions!G41 -> 5316.3735 | H25: =A25 -> Royal Matt Emulsion paint | I25: =Assumptions!K$41 -> 969 | J25: =Assumptions!L$41 -> 1055.03 | K25: =Assumptions!M$41 -> 1143.2839 | L25: =Assumptions!N$41 -> 1233.7707 | M25: =Assumptions!O$41 -> 1329.0934 | O25: =H25 -> Royal Matt Emulsion paint | P25: =Assumptions!S41 -> 242.25 | Q25: =Assumptions!T41 -> 263.7575 | R25: =Assumptions!U41 -> 285.82098 | S25: =Assumptions!V41 -> 308.44267 | T25: =Assumptions!W41 -> 332.27335
A26: =A15 -> Anti-bacterial Interior paint | B26: =Assumptions!C51 -> 4635 | C26: =Assumptions!D51 -> 5046.31 | D26: =Assumptions!E51 -> 5469.0766 | E26: =Assumptions!F51 -> 5903.6646 | F26: =Assumptions!G51 -> 6362.2717 | H26: =A26 -> Anti-bacterial Interior paint | I26: =Assumptions!K$51 -> 1158.75 | J26: =Assumptions!L$51 -> 1261.5775 | K26: =Assumptions!M$51 -> 1367.2691 | L26: =Assumptions!N$51 -> 1475.9161 | M26: =Assumptions!O$51 -> 1590.5679 | O26: =H26 -> Anti-bacterial Interior paint | P26: =Assumptions!S51 -> 289.6875 | Q26: =Assumptions!T51 -> 315.39438 | R26: =Assumptions!U51 -> 341.81729 | S26: =Assumptions!V51 -> 368.97904 | T26: =Assumptions!W51 -> 397.64198
A27: =A16 -> Silk emulsion | B27: =Assumptions!C60 -> 5408 | C27: =Assumptions!D60 -> 5890.928 | D27: =Assumptions!E60 -> 6401.0633 | E27: =Assumptions!F60 -> 6943.7781 | F27: =Assumptions!G60 -> 7529.5458 | H27: =A27 -> Silk emulsion | I27: =Assumptions!K$60 -> 1352 | J27: =Assumptions!L$60 -> 1472.732 | K27: =Assumptions!M$60 -> 1600.2658 | L27: =Assumptions!N$60 -> 1735.9445 | M27: =Assumptions!O$60 -> 1882.3865 | O27: =H27 -> Silk emulsion | P27: =Assumptions!S60 -> 338 | Q27: =Assumptions!T60 -> 368.183 | R27: =Assumptions!U60 -> 400.06646 | S27: =Assumptions!V60 -> 433.98613 | T27: =Assumptions!W60 -> 470.59661
A28: =A17 -> Weather resistent exterior paint | B28: =Assumptions!C69 -> 5276 | C28: =Assumptions!D69 -> 5741 | D28: =Assumptions!E69 -> 6232.3978 | E28: =Assumptions!F69 -> 6755.8653 | F28: =Assumptions!G69 -> 7321.1455 | H28: =A28 -> Weather resistent exterior paint | I28: =Assumptions!K69 -> 1319 | J28: =Assumptions!L69 -> 1435.25 | K28: =Assumptions!M69 -> 1558.0994 | L28: =Assumptions!N69 -> 1688.9663 | M28: =Assumptions!O69 -> 1830.2864 | O28: =H28 -> Weather resistent exterior paint | P28: =Assumptions!S69 -> 329.75 | Q28: =Assumptions!T69 -> 358.8125 | R28: =Assumptions!U69 -> 389.52486 | S28: =Assumptions!V69 -> 422.24158 | T28: =Assumptions!W69 -> 457.57159
A29: =A18 -> Super primer | B29: =Assumptions!C77 -> 2911 | C29: =Assumptions!D77 -> 3169.87 | D29: =Assumptions!E77 -> 3433.6433 | E29: =Assumptions!F77 -> 3701.647 | F29: =Assumptions!G77 -> 3982.2525 | H29: =A29 -> Super primer | I29: =Assumptions!K$77 -> 727.75 | J29: =Assumptions!L$77 -> 792.4675 | K29: =Assumptions!M$77 -> 858.41082 | L29: =Assumptions!N$77 -> 925.41175 | M29: =Assumptions!O$77 -> 995.56312 | O29: =H29 -> Super primer | P29: =Assumptions!S77 -> 181.9375 | Q29: =Assumptions!T77 -> 198.11687 | R29: =Assumptions!U77 -> 214.6027 | S29: =Assumptions!V77 -> 231.35294 | T29: =Assumptions!W77 -> 248.89078
A30: =A19 -> Synthetic Enamel | B30: =Assumptions!C85 -> 7670 | C30: =Assumptions!D85 -> 8347.36 | D30: =Assumptions!E85 -> 9068.313 | E30: =Assumptions!F85 -> 9842.7496 | F30: =Assumptions!G85 -> 10683.376 | H30: =A30 -> Synthetic Enamel | I30: =Assumptions!K$85 -> 1917.5 | J30: =Assumptions!L$85 -> 2086.84 | K30: =Assumptions!M$85 -> 2267.0782 | L30: =Assumptions!N$85 -> 2460.6874 | M30: =Assumptions!O$85 -> 2610.9906 | O30: =H30 -> Synthetic Enamel | P30: =Assumptions!S85 -> 479.375 | Q30: =Assumptions!T85 -> 521.71 | R30: =Assumptions!U85 -> 566.76956 | S30: =Assumptions!V85 -> 615.17185 | T30: =Assumptions!W85 -> 652.74766
O31: =H31
A32: Total RM cost PKR Mn | B32: =B24 -> 2026 | C32: =C24 -> 2027 | D32: =D24 -> 2028 | E32: =E24 -> 2029 | F32: =F24 -> 2030 | H32: =A32 -> Total RM cost PKR Mn | I32: =B32 -> 2026 | J32: =C32 -> 2027 | K32: =D32 -> 2028 | L32: =E32 -> 2029 | M32: =F32 -> 2030 | O32: =H32 -> Total RM cost PKR Mn | P32: =I32 -> 2026 | Q32: =J32 -> 2027 | R32: =K32 -> 2028 | S32: =L32 -> 2029 | T32: =M32 -> 2030
A33: =A25 -> Royal Matt Emulsion paint | B33: =B25*Sales!C5/1000000 -> 96.9 | C33: =C25*Sales!D5/1000000 -> 200.4557 | D33: =D25*Sales!E5/1000000 -> 391.0031 | E33: =E25*Sales!F5/1000000 -> 675.11931 | F33: =F25*Sales!G5/1000000 -> 1018.1919 | H33: =A33 -> Royal Matt Emulsion paint | I33: =I25*Sales!J5/1000000 -> 29.07 | J33: =J25*Sales!K5/1000000 -> 60.13671 | K33: =K25*Sales!L5/1000000 -> 117.30093 | L33: =L25*Sales!M5/1000000 -> 202.53579 | M33: =M25*Sales!N5/1000000 -> 305.45756 | O33: =H33 -> Royal Matt Emulsion paint | P33: =P25*Sales!Q5/1000000 -> 3.63375 | Q33: =Q25*Sales!R5/1000000 -> 7.5170888 | R33: =R25*Sales!S5/1000000 -> 14.662616 | S33: =S25*Sales!T5/1000000 -> 25.316974 | T33: =T25*Sales!U5/1000000 -> 38.182195
A34: =A26 -> Anti-bacterial Interior paint | B34: =B26*Sales!C6/1000000 -> 83.43 | C34: =C26*Sales!D6/1000000 -> 172.5838 | D34: =D26*Sales!E6/1000000 -> 336.67635 | E34: =E26*Sales!F6/1000000 -> 581.48735 | F34: =F26*Sales!G6/1000000 -> 877.32163 | H34: =A34 -> Anti-bacterial Interior paint | I34: =I26*Sales!J6/1000000 -> 26.65125 | J34: =J26*Sales!K6/1000000 -> 55.130937 | K34: =K26*Sales!L6/1000000 -> 107.54939 | L34: =L26*Sales!M6/1000000 -> 185.7529 | M34: =M26*Sales!N6/1000000 -> 280.25552 | O34: =H34 -> Anti-bacterial Interior paint | P34: =P26*Sales!Q6/1000000 -> 3.7659375 | Q34: =Q26*Sales!R6/1000000 -> 7.7902411 | R34: =R26*Sales!S6/1000000 -> 15.197196 | S34: =S26*Sales!T6/1000000 -> 26.247693 | T34: =T26*Sales!U6/1000000 -> 39.601324
A35: =A27 -> Silk emulsion | B35: =B27*Sales!C7/1000000 -> 124.384 | C35: =C27*Sales!D7/1000000 -> 257.43355 | D35: =D27*Sales!E7/1000000 -> 503.50764 | E35: =E27*Sales!F7/1000000 -> 873.91614 | F35: =F27*Sales!G7/1000000 -> 1326.6939 | H35: =A35 -> Silk emulsion | I35: =I27*Sales!J7/1000000 -> 36.504 | J35: =J27*Sales!K7/1000000 -> 75.551152 | K35: =K27*Sales!L7/1000000 -> 147.76855 | L35: =L27*Sales!M7/1000000 -> 256.47539 | M35: =M27*Sales!N7/1000000 -> 389.35583 | O35: =H35 -> Silk emulsion | P35: =P27*Sales!Q7/1000000 -> 5.746 | Q35: =Q27*Sales!R7/1000000 -> 11.892311 | R35: =R27*Sales!S7/1000000 -> 23.259864 | S35: =S27*Sales!T7/1000000 -> 40.371126 | T35: =T27*Sales!U7/1000000 -> 61.287491
A36: =A28 -> Weather resistent exterior paint | B36: =B28*Sales!C8/1000000 -> 158.28 | C36: =C28*Sales!D8/1000000 -> 327.237 | D36: =D28*Sales!E8/1000000 -> 639.44401 | E36: =E28*Sales!F8/1000000 -> 1109.0429 | F36: =F28*Sales!G8/1000000 -> 1682.5749 | H36: =A36 -> Weather resistent exterior paint | I36: =I28*Sales!J8/1000000 -> 46.165 | J36: =J28*Sales!K8/1000000 -> 95.444125 | K36: =K28*Sales!L8/1000000 -> 186.5045 | L36: =L28*Sales!M8/1000000 -> 323.47083 | M36: =M28*Sales!N8/1000000 -> 490.75102 | O36: =H36 -> Weather resistent exterior paint | P36: =P28*Sales!Q8/1000000 -> 8.24375 | Q36: =Q28*Sales!R8/1000000 -> 17.043594 | R36: =R28*Sales!S8/1000000 -> 33.304376 | S36: =S28*Sales!T8/1000000 -> 57.762648 | T36: =T28*Sales!U8/1000000 -> 87.634112
A37: =A29 -> Super primer | B37: =B29*Sales!C9/1000000 -> 101.885 | C37: =C29*Sales!D9/1000000 -> 210.79636 | D37: =D29*Sales!E9/1000000 -> 411.0071 | E37: =E29*Sales!F9/1000000 -> 708.93943 | F37: =F29*Sales!G9/1000000 -> 1067.7534 | H37: =A37 -> Super primer | I37: =I29*Sales!J9/1000000 -> 29.11 | J37: =J29*Sales!K9/1000000 -> 60.22753 | K37: =K29*Sales!L9/1000000 -> 117.4306 | L37: =L29*Sales!M9/1000000 -> 202.55412 | M37: =M29*Sales!N9/1000000 -> 305.0724 | O37: =H37 -> Super primer | P37: =P29*Sales!Q9/1000000 -> 5.458125 | Q37: =Q29*Sales!R9/1000000 -> 11.292662 | R37: =R29*Sales!S9/1000000 -> 22.018238 | S37: =S29*Sales!T9/1000000 -> 37.978898 | T37: =T29*Sales!U9/1000000 -> 57.201075
A38: =A30 -> Synthetic Enamel | B38: =B30*Sales!C10/1000000 -> 306.8 | C38: =C30*Sales!D10/1000000 -> 634.39936 | D38: =D30*Sales!E10/1000000 -> 1240.5452 | E38: =E30*Sales!F10/1000000 -> 2154.381 | F38: =F30*Sales!G10/1000000 -> 3273.7284 | H38: =A38 -> Synthetic Enamel | I38: =I30*Sales!J10/1000000 -> 86.2875 | J38: =J30*Sales!K10/1000000 -> 178.42482 | K38: =K30*Sales!L10/1000000 -> 348.90334 | L38: =L30*Sales!M10/1000000 -> 605.91966 | M38: =M30*Sales!N10/1000000 -> 900.10247 | O38: =H38 -> Synthetic Enamel | P38: =P30*Sales!Q10/1000000 -> 16.778125 | Q38: =Q30*Sales!R10/1000000 -> 34.693715 | R38: =R30*Sales!S10/1000000 -> 67.842316 | S38: =S30*Sales!T10/1000000 -> 117.81771 | T38: =T30*Sales!U10/1000000 -> 175.01992
A39: Total RM cost PKR Mn | B39: =SUM(B33:B38) -> 871.679 | C39: =SUM(C33:C38) -> 1802.9058 | D39: =SUM(D33:D38) -> 3522.1834 | E39: =SUM(E33:E38) -> 6102.8861 | F39: =SUM(F33:F38) -> 9246.2641 | H39: =A39 -> Total RM cost PKR Mn | I39: =SUM(I33:I38) -> 253.78775 | J39: =SUM(J33:J38) -> 524.91527 | K39: =SUM(K33:K38) -> 1025.4573 | L39: =SUM(L33:L38) -> 1776.7087 | M39: =SUM(M33:M38) -> 2670.9948 | O39: =H39 -> Total RM cost PKR Mn | P39: =SUM(P33:P38) -> 43.625687 | Q39: =SUM(Q33:Q38) -> 90.229611 | R39: =SUM(R33:R38) -> 176.28461 | S39: =SUM(S33:S38) -> 305.49505 | T39: =SUM(T33:T38) -> 458.92612
O40: =H40
...

Sheet Fixed Assets
A1: Fixed Assets Schedule | B1: (PKR Mn)
A3: 2026
B4: Begin Assets | C4: New Capex | D4: Updated Assets | E4: Depreciation | F4: Ending Assets
A5: Land | B5: 0 | C5: =Assumptions!C131 -> 22 | D5: =+B5+C5 -> 22 | E5: 0 | F5: =D5-E5 -> 22
A6: Building | B6: 0 | C6: =Assumptions!C132 -> 28 | D6: =+B6+C6 -> 28 | E6: 0 | F6: =D6-E6 -> 28
A7: Machinery | B7: 0 | C7: =Assumptions!C133 -> 60 | D7: =+B7+C7 -> 60 | E7: =D7*Assumptions!$C$139 -> 12 | F7: =D7-E7 -> 48
A8: Vehicles | B8: 0 | C8: =Assumptions!C134 -> 10 | D8: =+B8+C8 -> 10 | E8: =D8*Assumptions!$C$139 -> 2 | F8: =D8-E8 -> 8
A9: Retail outlets/Others | B9: 0 | C9: =Assumptions!C135 -> 18 | D9: =+B9+C9 -> 18 | E9: =D9*Assumptions!$C$139 -> 3.6 | F9: =D9-E9 -> 14.4
A10: Total | B10: =SUM(B5:B9) -> 0 | C10: =SUM(C5:C9) -> 138 | D10: =SUM(D5:D9) -> 138 | E10: =SUM(E5:E9) -> 17.6 | F10: =SUM(F5:F9) -> 120.4
A12: =+A3+1 -> 2027
B13: Begin Assets | C13: New Capex | D13: Updated Assets | E13: Depreciation | F13: Ending Assets
A14: =A5 -> Land | B14: =F5 -> 22 | C14: =Assumptions!D131 -> 0 | D14: =+B14+C14 -> 22 | E14: =+E5 -> 0 | F14: =D14-E14 -> 22
A15: =A6 -> Building | B15: =F6 -> 28 | C15: =Assumptions!D132 -> 0 | D15: =+B15+C15 -> 28 | E15: =E6 -> 0 | F15: =D15-E15 -> 28
A16: =A7 -> Machinery | B16: =F7 -> 48 | C16: =Assumptions!D133 -> 10 | D16: =+B16+C16 -> 58 | E16: =D16*Assumptions!$C$139 -> 11.6 | F16: =D16-E16 -> 46.4
A17: =A8 -> Vehicles | B17: =F8 -> 8 | C17: =Assumptions!D134 -> 2 | D17: =+B17+C17 -> 10 | E17: =D17*Assumptions!$C$139 -> 2 | F17: =D17-E17 -> 8
A18: =A9 -> Retail outlets/Others | B18: =F9 -> 14.4 | C18: =Assumptions!D135 -> 5 | D18: =+B18+C18 -> 19.4 | E18: =D18*Assumptions!$C$139 -> 3.88 | F18: =D18-E18 -> 15.52
A19: Total | B19: =SUM(B14:B18) -> 120.4 | C19: =SUM(C14:C18) -> 17 | D19: =SUM(D14:D18) -> 137.4 | E19: =SUM(E14:E18) -> 17.48 | F19: =SUM(F14:F18) -> 119.92
A21: =+A12+1 -> 2028
B22: Begin Assets | C22: New Capex | D22: Updated Assets | E22: Depreciation | F22: Ending Assets
A23: =A14 -> Land | B23: =F14 -> 22 | C23: =Assumptions!E131 -> 0 | D23: =+B23+C23 -> 22 | E23: =+E14 -> 0 | F23: =D23-E23 -> 22
A24: =A15 -> Building | B24: =F15 -> 28 | C24: =Assumptions!E132 -> 0 | D24: =+B24+C24 -> 28 | E24: =E6 -> 0 | F24: =D24-E24 -> 28
A25: =A16 -> Machinery | B25: =F16 -> 46.4 | C25: =Assumptions!E133 -> 6 | D25: =+B25+C25 -> 52.4 | E25: =D25*Assumptions!$C$139 -> 10.48 | F25: =D25-E25 -> 41.92
A26: =A17 -> Vehicles | B26: =F17 -> 8 | C26: =Assumptions!E134 -> 1 | D26: =+B26+C26 -> 9 | E26: =D26*Assumptions!$C$139 -> 1.8 | F26: =D26-E26 -> 7.2
A27: =A18 -> Retail outlets/Others | B27: =F18 -> 15.52 | C27: =Assumptions!E135 -> 4 | D27: =+B27+C27 -> 19.52 | E27: =D27*Assumptions!$C$139 -> 3.904 | F27: =D27-E27 -> 15.616
A28: Total | B28: =SUM(B23:B27) -> 119.92 | C28: =SUM(C23:C27) -> 11 | D28: =SUM(D23:D27) -> 130.92 | E28: =SUM(E23:E27) -> 16.184 | F28: =SUM(F23:F27) -> 114.736
A30: =+A21+1 -> 2029
B31: Begin Assets | C31: New Capex | D31: Updated Assets | E31: Depreciation | F31: Ending Assets
A32: =A23 -> Land | B32: =F23 -> 22 | C32: =Assumptions!F131 -> 0 | D32: =+B32+C32 -> 22 | E32: =+E23 -> 0 | F32: =D32-E32 -> 22
A33: =A24 -> Building | B33: =F24 -> 28 | C33: =Assumptions!F132 -> 0 | D33: =+B33+C33 -> 28 | E33: =E6 -> 0 | F33: =D33-E33 -> 28
A34: =A25 -> Machinery | B34: =F25 -> 41.92 | C34: =Assumptions!F133 -> 6 | D34: =+B34+C34 -> 47.92 | E34: =D34*Assumptions!$C$139 -> 9.584 | F34: =D34-E34 -> 38.336
A35: =A26 -> Vehicles | B35: =F26 -> 7.2 | C35: =Assumptions!F134 -> 1 | D35: =+B35+C35 -> 8.2 | E35: =D35*Assumptions!$C$139 -> 1.64 | F35: =D35-E35 -> 6.56
A36: =A27 -> Retail outlets/Others | B36: =F27 -> 15.616 | C36: =Assumptions!F135 -> 4 | D36: =+B36+C36 -> 19.616 | E36: =D36*Assumptions!$C$139 -> 3.9232 | F36: =D36-E36 -> 15.6928
A37: Total | B37: =SUM(B32:B36) -> 114.736 | C37: =SUM(C32:C36) -> 11 | D37: =SUM(D32:D36) -> 125.736 | E37: =SUM(E32:E36) -> 15.1472 | F37: =SUM(F32:F36) -> 110.5888
A39: =+A30+1 -> 2030
B40: Begin Assets | C40: New Capex | D40: Updated Assets | E40: Depreciation | F40: Ending Assets
A41: =A32 -> Land | B41: =F32 -> 22 | C41: =Assumptions!G131 -> 0 | D41: =+B41+C41 -> 22 | E41: =+E32 -> 0 | F41: =D41-E41 -> 22
A42: =A33 -> Building | B42: =F33 -> 28 | C42: =Assumptions!G132 -> 0 | D42: =+B42+C42 -> 28 | E42: =E6 -> 0 | F42: =D42-E42 -> 28
A43: =A34 -> Machinery | B43: =F34 -> 38.336 | C43: =Assumptions!G133 -> 5 | D43: =+B43+C43 -> 43.336 | E43: =D43*Assumptions!$C$139 -> 8.6672 | F43: =D43-E43 -> 34.6688
A44: =A35 -> Vehicles | B44: =F35 -> 6.56 | C44: =Assumptions!G134 -> 1 | D44: =+B44+C44 -> 7.56 | E44: =D44*Assumptions!$C$139 -> 1.512 | F44: =D44-E44 -> 6.048
A45: =A36 -> Retail outlets/Others | B45: =F36 -> 15.6928 | C45: =Assumptions!G135 -> 5 | D45: =+B45+C45 -> 20.6928 | E45: =D45*Assumptions!$C$139 -> 4.13856 | F45: =D45-E45 -> 16.55424
...

Sheet Working Capital
A1: Working Capital
D3: =Assumptions!D2 -> 2026 | E3: =Assumptions!E2 -> 2027 | F3: =Assumptions!F2 -> 2028 | G3: =Assumptions!G2 -> 2029 | H3: =Assumptions!H2 -> 2030
A5: AR Turnover | B5: (times) | D5: =365/Assumptions!C123 -> 8.1111111 | E5: =365/Assumptions!D123 -> 8.1111111 | F5: =365/Assumptions!E123 -> 9.125 | G5: =365/Assumptions!F123 -> 9.125 | H5: =365/Assumptions!G123 -> 9.125
A6: AP Turnover | B6: (times) | D6: =365/Assumptions!C124 -> 4.5625 | E6: =365/Assumptions!D124 -> 4.8666667 | F6: =365/Assumptions!E124 -> 5.2142857 | G6: =365/Assumptions!F124 -> 5.6153846 | H6: =365/Assumptions!G124 -> 5.6153846
A7: Inv Turnover | B7: (times) | D7: =365/Assumptions!C125 -> 6.6363636 | E7: =365/Assumptions!D125 -> 7.3 | F7: =365/Assumptions!E125 -> 8.1111111 | G7: =365/Assumptions!F125 -> 9.125 | H7: =365/Assumptions!G125 -> 9.125
A9: Acc Rec | B9: PKR Mn | D9: ='Income Statement'!B$6/'Working Capital'!D5 -> 362.30976 | E9: ='Income Statement'!C$6/'Working Capital'!E5 -> 752.56569 | F9: ='Income Statement'!D$6/'Working Capital'!F5 -> 1303.078 | G9: ='Income Statement'!E$6/'Working Capital'!G5 -> 2241.0178 | H9: ='Income Statement'!F$6/'Working Capital'!H5 -> 3342.8587
A10: Acc Pay | B10: PKR Mn | D10: ='Income Statement'!B$7/'Working Capital'!D6 -> 300.69134 | E10: ='Income Statement'!C$7/'Working Capital'!E6 -> 583.16587 | F10: ='Income Statement'!D$7/'Working Capital'!F6 -> 1062.5522 | G10: ='Income Statement'!E$7/'Working Capital'!G6 -> 1706.5583 | H10: ='Income Statement'!F$7/'Working Capital'!H6 -> 2575.147
A11: Inv | B11: PKR Mn | D11: ='Income Statement'!B$7/'Working Capital'!D7 -> 206.7253 | E11: ='Income Statement'!C$7/'Working Capital'!E7 -> 388.77725 | F11: ='Income Statement'!D$7/'Working Capital'!F7 -> 683.06925 | G11: ='Income Statement'!E$7/'Working Capital'!G7 -> 1050.1897 | H11: ='Income Statement'!F$7/'Working Capital'!H7 -> 1584.7058

Sheet Equity
A1: Equity
C2: =Assumptions!D2 -> 2026 | D2: =Assumptions!E2 -> 2027 | E2: =Assumptions!F2 -> 2028 | F2: =Assumptions!G2 -> 2029 | G2: =Assumptions!H2 -> 2030
A3: Begin Capital | C3: 0 | D3: =C6 -> 100 | E3: =D6 -> 300 | F3: =E6 -> 400 | G3: =F6 -> 400
A4: Capital Injected | C4: =Assumptions!C143 -> 100 | D4: =Assumptions!D143 -> 200 | E4: =Assumptions!E143 -> 100 | F4: =Assumptions!F143 -> 0 | G4: =Assumptions!G143 -> 0
A5: Capital Withdrawn | C5: =Assumptions!C144 -> 0 | D5: =Assumptions!D144 -> 0 | E5: =Assumptions!E144 -> 0 | F5: =Assumptions!F144 -> 0 | G5: =Assumptions!G144 -> 0
A6: Ending Capital | C6: =C3+C4-C5 -> 100 | D6: =D3+D4-D5 -> 300 | E6: =E3+E4-E5 -> 400 | F6: =F3+F4-F5 -> 400 | G6: =G3+G4-G5 -> 400
A9: Begin Retained Earnings | C9: 0 | D9: =C12 -> 531.50342 | E9: =D12 -> 1671.7078 | F9: =E12 -> 3935.1625 | G9: =F12 -> 8044.5327
A10: Net Income | C10: ='Income Statement'!B18 -> 590.55935 | D10: ='Income Statement'!C18 -> 1341.4169 | E10: ='Income Statement'!D18 -> 2829.3184 | F10: ='Income Statement'!E18 -> 5136.7127 | G10: ='Income Statement'!F18 -> 7874.2444
A11: Dividend Paid | C11: =IF(C10>=0,C10*Assumptions!C$146,0) -> 59.055935 | D11: =IF(D10>=0,D10*Assumptions!D$146,0) -> 201.21253 | E11: =IF(E10>=0,E10*Assumptions!E$146,0) -> 565.86369 | F11: =IF(F10>=0,F10*Assumptions!F$146,0) -> 1027.3425 | G11: =IF(G10>=0,G10*Assumptions!G$146,0) -> 1574.8489
A12: Ending Retained Earnings | C12: =C9+C10-C11 -> 531.50342 | D12: =D9+D10-D11 -> 1671.7078 | E12: =E9+E10-E11 -> 3935.1625 | F12: =F9+F10-F11 -> 8044.5327 | G12: =G9+G10-G11 -> 14343.928

Sheet Short Term Loan
A1: Short Term Loan | C1: (PKR Mn)
C3: ='Income Statement'!C3 -> 2027 | D3: ='Income Statement'!D3 -> 2028 | E3: ='Income Statement'!E3 -> 2029 | F3: ='Income Statement'!F3 -> 2030 | G3: ='Income Statement'!G3
A5: Beginning Bal | C5: 0 | D5: =+C7 -> 0 | E5: =+D7 -> 0 | F5: =+E7 -> 0 | G5: =+F7 -> 0
A6: ST Loan Disbursed/ (Repaid) | C6: =-MIN(C5,('Cash Flow Statement'!C31+'Cash Flow Statement'!C11+'Cash Flow Statement'!C20+'Cash Flow Statement'!C23+'Cash Flow Statement'!C24+'Cash Flow Statement'!C26+'Cash Flow Statement'!C27)) -> 0 | D6: =-MIN(D5,('Cash Flow Statement'!D31+'Cash Flow Statement'!D11+'Cash Flow Statement'!D20+'Cash Flow Statement'!D23+'Cash Flow Statement'!D24+'Cash Flow Statement'!D26+'Cash Flow Statement'!D27)) -> 0 | E6: =-MIN(E5,('Cash Flow Statement'!E31+'Cash Flow Statement'!E11+'Cash Flow Statement'!E20+'Cash Flow Statement'!E23+'Cash Flow Statement'!E24+'Cash Flow Statement'!E26+'Cash Flow Statement'!E27)) -> 0 | F6: =-MIN(F5,('Cash Flow Statement'!F31+'Cash Flow Statement'!F11+'Cash Flow Statement'!F20+'Cash Flow Statement'!F23+'Cash Flow Statement'!F24+'Cash Flow Statement'!F26+'Cash Flow Statement'!F27)) -> 0 | G6: =-MIN(G5,('Cash Flow Statement'!G31+'Cash Flow Statement'!G11+'Cash Flow Statement'!G20+'Cash Flow Statement'!G23+'Cash Flow Statement'!G24+'Cash Flow Statement'!G26+'Cash Flow Statement'!G27)) -> 0
A7: Ending Bal | C7: =+C5+C6 -> 0 | D7: =+D5+D6 -> 0 | E7: =+E5+E6 -> 0 | F7: =+F5+F6 -> 0 | G7: =+G5+G6 -> 0
